<?xml version="1.0" ?>
<sdf version="1.4">
  <world name="quadcopter_world">
    <!-- A ground plane -->
    <include>
      <uri>model://ground_plane</uri>
    </include>
    
    <!-- A light source -->
    <include>
      <uri>model://sun</uri>
    </include>
    
    <!-- Quadcopter model -->
    <model name="quadcopter">
      <pose>0 0 0 0 0 0</pose>
      
      

      <!-- Center Cylinder -->
      <link name="center_cylinder">
        <pose>0 0 0.15 0 0 0</pose>
        <collision name="collision">
          <geometry>
            <cylinder>
              <radius>0.15</radius>
              <length>0.07</length>
            </cylinder>
          </geometry>
        </collision>
        <visual name="visual">
          <geometry>
            <cylinder>
              <radius>0.15</radius>
              <length>0.07</length>
            </cylinder>
          </geometry>
          <material> 
            <ambient>0.5 0 0 1</ambient>
            <diffuse>0.5 0 0 1</diffuse>
            <specular>0.5 0 0 1</specular>
            <emissive>0.5 0 0 1</emissive>
          </material> 
        </visual>
      </link>

      <!-- Arm 1 -->
      <link name="arm_1">
        <pose>0.35 0 0.15 0 0 0</pose>
        <collision name="collision">
          <geometry>
            <box>
              <size>0.7 0.05 0.05</size>
            </box>
          </geometry>
        </collision>
        <visual name="visual">
          <geometry>
            <box>
              <size>0.7 0.05 0.05</size>
            </box>
          </geometry>
          <material> 
            <ambient>0.1 0.1 0.6 1</ambient>
            <diffuse>0.1 0.1 0.6 1</diffuse>
            <specular>0.1 0.1 0.6 1</specular>
            <emissive>0.1 0.1 0.6 1</emissive>
          </material> 
        </visual>
        <collision name="base1_collision">
          <geometry>
            <box>
              <size>0.02 0.02 0.1</size>
            </box>
          </geometry>
        </collision>
        <visual name="base_visual">
          <geometry>
            <box>
              <size>0.02 0.02 0.1</size>
            </box>
          </geometry>
          <material> 
            <ambient>0.1 0.1 0.6 1</ambient>
            <diffuse>0.1 0.1 0.6 1</diffuse>
            <specular>0.1 0.1 0.6 1</specular>
            <emissive>0.1 0.1 0.6 1</emissive>
          </material> 
          <pose>0 0 -0.025 0 0 0</pose>
        </visual>
      </link>

      <!-- Arm 2 -->
      <link name="arm_2">
        <pose>0 0.35 0.15 0 0 1.5708</pose>
        <collision name="collision">
          <geometry>
            <box>
              <size>0.7 0.05 0.05</size>
            </box>
          </geometry>
        </collision>
        <visual name="visual">
          <geometry>
            <box>
              <size>0.7 0.05 0.05</size>
            </box>
          </geometry>
          <material> 
            <ambient>0.1 0.1 0.6 1</ambient>
            <diffuse>0.1 0.1 0.6 1</diffuse>
            <specular>0.1 0.1 0.6 1</specular>
            <emissive>0.1 0.1 0.6 1</emissive>
          </material> 
        </visual>
        <collision name="base2_collision">
          <geometry>
            <box>
              <size>0.02 0.02 0.1</size>
            </box>
          </geometry>
        </collision>
        <visual name="base_visual">
          <geometry>
            <box>
              <size>0.02 0.02 0.1</size>
            </box>
          </geometry>
          <material> 
            <ambient>0.1 0.1 0.6 1</ambient>
            <diffuse>0.1 0.1 0.6 1</diffuse>
            <specular>0.1 0.1 0.6 1</specular>
            <emissive>0.1 0.1 0.6 1</emissive>
          </material> 
          <pose>0 0 -0.025 0 0 0</pose>
        </visual>
      </link>

      <!-- Arm 3 -->
      <link name="arm_3">
        <pose>-0.35 0 0.15 0 0 0</pose>
        <collision name="collision">
          <geometry>
            <box>
              <size>0.7 0.05 0.05</size>
            </box>
          </geometry>
        </collision>
        <visual name="visual">
          <geometry>
            <box>
              <size>0.7 0.05 0.05</size>
            </box>
          </geometry>
          <material> 
            <ambient>0.1 0.1 0.6 1</ambient>
            <diffuse>0.1 0.1 0.6 1</diffuse>
            <specular>0.1 0.1 0.6 1</specular>
            <emissive>0.1 0.1 0.6 1</emissive>
          </material> 
        </visual>
        <collision name="base3_collision">
          <geometry>
            <box>
              <size>0.02 0.02 0.1</size>
            </box>
          </geometry>
        </collision>
        <visual name="base_visual">
          <geometry>
            <box>
              <size>0.02 0.02 0.1</size>
            </box>
          </geometry>
          <material> 
            <ambient>0.1 0.1 0.6 1</ambient>
            <diffuse>0.1 0.1 0.6 1</diffuse>
            <specular>0.1 0.1 0.6 1</specular>
            <emissive>0.1 0.1 0.6 1</emissive>
          </material> 
          <pose>0 0 -0.025 0 0 0</pose>
        </visual>
      </link>

      <!-- Arm 4 -->
      <link name="arm_4">
        <pose>0 -0.35 0.15 0 0 1.5708</pose>
        <collision name="collision">
          <geometry>
            <box>
              <size>0.7 0.05 0.05</size>
            </box>
          </geometry>
        </collision>
        <visual name="visual">
          <geometry>
            <box>
              <size>0.7 0.05 0.05</size>
            </box>
          </geometry>
          <material> 
            <ambient>0.1 0.1 0.6 1</ambient>
            <diffuse>0.1 0.1 0.6 1</diffuse>
            <specular>0.1 0.1 0.6 1</specular>
            <emissive>0.1 0.1 0.6 1</emissive>
          </material> 
        </visual>
        <collision name="base4_collision">
          <geometry>
            <box>
              <size>0.02 0.02 0.1</size>
            </box>
          </geometry>
        </collision>
        <visual name="base_visual">
          <geometry>
            <box>
              <size>0.02 0.02 0.1</size>
            </box>
          </geometry>
          <material> 
            <ambient>0.1 0.1 0.6 1</ambient>
            <diffuse>0.1 0.1 0.6 1</diffuse>
            <specular>0.1 0.1 0.6 1</specular>
            <emissive>0.1 0.1 0.6 1</emissive>
          </material> 
          <pose>0 0 -0.025 0 0 0</pose>
        </visual>
      </link>




      <!-- Rotor 1 -->
      <link name="rotor_1">
        <pose>0.65 0 0.18 0 0 0</pose>
        <collision name="collision">
          <geometry>
            <cylinder>
              <radius>0.05</radius>
              <length>0.01</length>
            </cylinder>
          </geometry>
        </collision>
        <visual name="visual">
          <geometry>
            <cylinder>
              <radius>0.05</radius>
              <length>0.01</length>
            </cylinder>
          </geometry>
          <material> 
            <ambient>0.2 0.2 0.2 1</ambient>
            <diffuse>0.2 0.2 0.2 1</diffuse>
            <specular>0.2 0.2 0.2 1</specular>
            <emissive>0.2 0.2 0.2 1</emissive>
          </material>
        </visual>

        <!-- Propeller blades -->
        <collision name="blade_1_collision">
          <geometry>
            <box>
              <size>0.2 0.04 0.01</size>
            </box>
          </geometry>
          <pose>0 0.1 0 0 0 1.5708</pose>
        </collision>
        <visual name="blade_1_visual">
          <geometry>
            <box>
              <size>0.2 0.04 0.01</size>
            </box>
          </geometry>
          <material> 
            <ambient>0.2 0.2 0.2 1</ambient>
            <diffuse>0.2 0.2 0.2 1</diffuse>
            <specular>0.2 0.2 0.2 1</specular>
            <emissive>0.2 0.2 0.2 1</emissive>
          </material>
          <pose>0 0.1 0 0 0 1.5708</pose>
        </visual>

        <collision name="blade_2_collision">
          <geometry>
            <box>
              <size>0.2 0.04 0.01</size>
            </box>
          </geometry>
          <pose>0 -0.1 0 0 0 1.5708</pose>
        </collision>
        <visual name="blade_2_visual">
          <geometry>
            <box>
              <size>0.2 0.04 0.01</size>
            </box>
          </geometry>
          <material> 
            <ambient>0.2 0.2 0.2 1</ambient>
            <diffuse>0.2 0.2 0.2 1</diffuse>
            <specular>0.2 0.2 0.2 1</specular>
            <emissive>0.2 0.2 0.2 1</emissive>
          </material>
          <pose>0 -0.1 0 0 0 1.5708</pose>
        </visual>
      </link>

      <!-- Rotor 2 -->
      <link name="rotor_2">
        <pose>0 0.65 0.18 0 0 0</pose>
        <collision name="collision">
          <geometry>
            <cylinder>
              <radius>0.05</radius>
              <length>0.01</length>
            </cylinder>
          </geometry>
        </collision>
        <visual name="visual">
          <geometry>
            <cylinder>
              <radius>0.05</radius>
              <length>0.01</length>
            </cylinder>
          </geometry>
          <material> 
            <ambient>0.2 0.2 0.2 1</ambient>
            <diffuse>0.2 0.2 0.2 1</diffuse>
            <specular>0.1 0.1 0.1 1</specular>
            <emissive>0 0 0 1</emissive>
          </material>          
        </visual>

        <!-- Propeller blades -->
        <collision name="blade_1_collision">
          <geometry>
            <box>
              <size>0.2 0.04 0.01</size>
            </box>
          </geometry>
          <pose>0.1 0 0 0 0 0</pose>
        </collision>
        <visual name="blade_1_visual">
          <geometry>
            <box>
              <size>0.2 0.04 0.01</size>
            </box>
          </geometry>
          <material> 
            <ambient>0.2 0.2 0.2 1</ambient>
            <diffuse>0.2 0.2 0.2 1</diffuse>
            <specular>0.1 0.1 0.1 1</specular>
            <emissive>0 0 0 1</emissive>
          </material>         
          <pose>0.1 0 0 0 0 0</pose>
        </visual>

        <collision name="blade_2_collision">
          <geometry>
            <box>
              <size>0.2 0.04 0.01</size>
            </box>
          </geometry>
          <pose>-0.1 0 0 0 0 0</pose>
        </collision>
        <visual name="blade_2_visual">
          <geometry>
            <box>
              <size>0.2 0.04 0.01</size>
            </box>
          </geometry>
          <material> 
            <ambient>0.2 0.2 0.2 1</ambient>
            <diffuse>0.2 0.2 0.2 1</diffuse>
            <specular>0.1 0.1 0.1 1</specular>
            <emissive>0 0 0 1</emissive>
          </material>
          <pose>-0.1 0 0 0 0 0</pose>
        </visual>
      </link>

      <!-- Rotor 3 -->
      <link name="rotor_3">
        <pose>-0.65 0 0.18 0 0 0</pose>
        <collision name="collision">
          <geometry>
            <cylinder>
              <radius>0.05</radius>
              <length>0.01</length>
            </cylinder>
          </geometry>
        </collision>
        <visual name="visual">
          <geometry>
            <cylinder>
              <radius>0.05</radius>
              <length>0.01</length>
            </cylinder>
          </geometry>
          <material> 
            <ambient>0.2 0.2 0.2 1</ambient>
            <diffuse>0.2 0.2 0.2 1</diffuse>
            <specular>0.2 0.2 0.2 1</specular>
            <emissive>0.2 0.2 0.2 1</emissive>
          </material>
        </visual>

        <!-- Propeller blades -->
        <collision name="blade_1_collision">
          <geometry>
            <box>
              <size>0.2 0.04 0.01</size>
            </box>
          </geometry>
          <pose>0 0.1 0 0 0 1.5708</pose>
        </collision>
        <visual name="blade_1_visual">
          <geometry>
            <box>
              <size>0.2 0.04 0.01</size>
            </box>
          </geometry>
          <material> 
            <ambient>0.2 0.2 0.2 1</ambient>
            <diffuse>0.2 0.2 0.2 1</diffuse>
            <specular>0.2 0.2 0.2 1</specular>
            <emissive>0.2 0.2 0.2 1</emissive>
          </material>
          <pose>0 0.1 0 0 0 1.5708</pose>
        </visual>

        <collision name="blade_2_collision">
          <geometry>
            <box>
              <size>0.2 0.04 0.01</size>
            </box>
          </geometry>
          <pose>0 -0.1 0 0 0 1.5708</pose>
        </collision>
        <visual name="blade_2_visual">
          <geometry>
            <box>
              <size>0.2 0.04 0.01</size>
            </box>
          </geometry>
          <material> 
            <ambient>0.2 0.2 0.2 1</ambient>
            <diffuse>0.2 0.2 0.2 1</diffuse>
            <specular>0.2 0.2 0.2 1</specular>
            <emissive>0.2 0.2 0.2 1</emissive>
          </material>
          <pose>0 -0.1 0 0 0 1.5708</pose>
        </visual>
      </link>

      <!-- Rotor 4 -->
      <link name="rotor_4">
        <pose>0 -0.65 0.18 0 0 0</pose>
        <collision name="collision">
          <geometry>
            <cylinder>
              <radius>0.05</radius>
              <length>0.01</length>
            </cylinder>
          </geometry>
        </collision>
        <visual name="visual">
          <geometry>
            <cylinder>
              <radius>0.05</radius>
              <length>0.01</length>
            </cylinder>
          </geometry>
          <material> 
            <ambient>0.2 0.2 0.2 1</ambient>
            <diffuse>0.2 0.2 0.2 1</diffuse>
            <specular>0.1 0.1 0.1 1</specular>
            <emissive>0 0 0 1</emissive>
          </material>
        </visual>

        <!-- Propeller blades -->
        <collision name="blade_1_collision">
          <geometry>
            <box>
              <size>0.2 0.04 0.01</size>
            </box>
          </geometry>
          <pose>0.1 0 0 0 0 0</pose>
        </collision>
        <visual name="blade_1_visual">
          <geometry>
            <box>
              <size>0.2 0.04 0.01</size>
            </box>
          </geometry>
          <material> 
            <ambient>0.2 0.2 0.2 1</ambient>
            <diffuse>0.2 0.2 0.2 1</diffuse>
            <specular>0.1 0.1 0.1 1</specular>
            <emissive>0 0 0 1</emissive>
          </material>          
          <pose>0.1 0 0 0 0 0</pose>
        </visual>

        <collision name="blade_2_collision">
          <geometry>
            <box>
              <size>0.2 0.04 0.01</size>
            </box>
          </geometry>
          <pose>-0.1 0 0 0 0 0</pose>
        </collision>
        <visual name="blade_2_visual">
          <geometry>
            <box>
              <size>0.2 0.04 0.01</size>
            </box>
          </geometry>
          <material> 
            <ambient>0.2 0.2 0.2 1</ambient>
            <diffuse>0.2 0.2 0.2 1</diffuse>
            <specular>0.1 0.1 0.1 1</specular>
            <emissive>0 0 0 1</emissive>
          </material>          
          <pose>-0.1 0 0 0 0 0</pose>
        </visual>
      </link>


      <!-- Lidar -->
      <link name="lidar">
        <visual name="visual">
          <pose>0 0 0.2 0 0 0</pose>
          <geometry>
            <cylinder>
              <radius>0.05</radius>
              <length>0.03</length>
            </cylinder>
          </geometry>
          <material>
            <ambient>0.0 1.0 0.0 1</ambient>
            <diffuse>0.0 1.0 0.0 1</diffuse>
          </material>
        </visual>
        <collision name="collision">
          <geometry>
            <cylinder>
              <radius>0.05</radius>
              <length>0.03</length>
            </cylinder>
          </geometry>
        </collision>
        <sensor name="lidar_sensor" type="ray">
          <pose>0 0 0.21 0 0 0</pose>
          <always_on>1</always_on>
          <update_rate>10</update_rate>
          <visualize>true</visualize>
          <ray>
            <scan>
              <horizontal>
                <samples>640</samples>
                <resolution>1</resolution>
                <min_angle>-3.14159</min_angle>
                <max_angle>3.14159</max_angle>
              </horizontal>
              <vertical>
                <samples>1</samples>
                <resolution>1</resolution>
                <min_angle>0</min_angle>
                <max_angle>0</max_angle>
              </vertical>
            </scan>
            <range>
              <min>0.1</min>
              <max>15.0</max>
              <resolution>0.01</resolution>
            </range>
          </ray>
        </sensor>
      </link>
      

      <!-- Ultrasonic sensors-->
      <link name="ultrasonic_1">
        <visual name="visual">
          <pose>0.1 0.1 0.115 0 0 0</pose>
          <geometry>
            <cylinder>
              <radius>0.01</radius>
              <length>0.005</length>
            </cylinder>
          </geometry>
          <material>
            <ambient>1.0 1.0 0.0 1</ambient>
            <diffuse>1.0 1.0 0.0 1</diffuse>
          </material>
        </visual>
        <collision name="collision">
          <geometry>
            <cylinder>
              <radius>0.01</radius>
              <length>0.005</length>
            </cylinder>
          </geometry>
        </collision>
        <sensor name="ultrasonic_sensor" type="ray">
          <pose>0.1 0.1 0.115 0 0 0</pose>
          <always_on>1</always_on>
          <update_rate>10</update_rate>
          <visualize>true</visualize>
          <ray>
            <scan>
              <horizontal>
                <samples>640</samples>
                <resolution>1</resolution>
                <min_angle>0.39</min_angle>
                <max_angle>1.18</max_angle>
              </horizontal>
              <vertical>
                <samples>1</samples>
                <resolution>1</resolution>
                <min_angle>0</min_angle>
                <max_angle>0</max_angle>
              </vertical>
            </scan>
            <range>
              <min>0.1</min>
              <max>4.0</max>
              <resolution>0.01</resolution>
            </range>
          </ray>
        </sensor>
      </link>



      <link name="ultrasonic_2">
        <visual name="visual">
          <pose>-0.1 0.1 0.115 0 0 0</pose>
          <geometry>
            <cylinder>
              <radius>0.01</radius>
              <length>0.005</length>
            </cylinder>
          </geometry>
          <material>
            <ambient>1.0 1.0 0.0 1</ambient>
            <diffuse>1.0 1.0 0.0 1</diffuse>
          </material>
        </visual>
        <collision name="collision">
          <geometry>
            <cylinder>
              <radius>0.01</radius>
              <length>0.005</length>
            </cylinder>
          </geometry>
        </collision>
        <sensor name="ultrasonic_sensor" type="ray">
          <pose>-0.1 0.1 0.115 0 0 0</pose>
          <always_on>1</always_on>
          <update_rate>10</update_rate>
          <visualize>true</visualize>
          <ray>
            <scan>
              <horizontal>
                <samples>640</samples>
                <resolution>1</resolution>
                <min_angle>1.96</min_angle>
                <max_angle>2.75</max_angle>
              </horizontal>
              <vertical>
                <samples>1</samples>
                <resolution>1</resolution>
                <min_angle>0</min_angle>
                <max_angle>0</max_angle>
              </vertical>
            </scan>
            <range>
              <min>0.1</min>
              <max>4.0</max>
              <resolution>0.01</resolution>
            </range>
          </ray>
        </sensor>
      </link>



      <link name="ultrasonic_3">
        <visual name="visual">
          <pose>-0.1 -0.1 0.115 0 0 0</pose>
          <geometry>
            <cylinder>
              <radius>0.01</radius>
              <length>0.005</length>
            </cylinder>
          </geometry>
          <material>
            <ambient>1.0 1.0 0.0 1</ambient>
            <diffuse>1.0 1.0 0.0 1</diffuse>
          </material>
        </visual>
        <collision name="collision">
          <geometry>
            <cylinder>
              <radius>0.01</radius>
              <length>0.005</length>
            </cylinder>
          </geometry>
        </collision>
        <sensor name="ultrasonic_sensor" type="ray">
          <pose>-0.1 -0.1 0.115 0 0 0</pose>
          <always_on>1</always_on>
          <update_rate>10</update_rate>
          <visualize>true</visualize>
          <ray>
            <scan>
              <horizontal>
                <samples>640</samples>
                <resolution>1</resolution>
                <min_angle>-1.96</min_angle>
                <max_angle>-2.75</max_angle>
              </horizontal>
              <vertical>
                <samples>1</samples>
                <resolution>1</resolution>
                <min_angle>0</min_angle>
                <max_angle>0</max_angle>
              </vertical>
            </scan>
            <range>
              <min>0.1</min>
              <max>4.0</max>
              <resolution>0.01</resolution>
            </range>
          </ray>
        </sensor>
      </link>



      <link name="ultrasonic_4">
        <visual name="visual">
          <pose>0.1 -0.1 0.115 0 0 0</pose>
          <geometry>
            <cylinder>
              <radius>0.01</radius>
              <length>0.005</length>
            </cylinder>
          </geometry>
          <material>
            <ambient>1.0 1.0 0.0 1</ambient>
            <diffuse>1.0 1.0 0.0 1</diffuse>
          </material>
        </visual>
        <collision name="collision">
          <geometry>
            <cylinder>
              <radius>0.01</radius>
              <length>0.005</length>
            </cylinder>
          </geometry>
        </collision>
        <sensor name="ultrasonic_sensor" type="ray">
          <pose>0.1 -0.1 0.115 0 0 0</pose>
          <always_on>1</always_on>
          <update_rate>10</update_rate>
          <visualize>true</visualize>
          <ray>
            <scan>
              <horizontal>
                <samples>640</samples>
                <resolution>1</resolution>
                <min_angle>-0.39</min_angle>
                <max_angle>-1.18</max_angle>
              </horizontal>
              <vertical>
                <samples>1</samples>
                <resolution>1</resolution>
                <min_angle>0</min_angle>
                <max_angle>0</max_angle>
              </vertical>
            </scan>
            <range>
              <min>0.1</min>
              <max>4.0</max>
              <resolution>0.01</resolution>
            </range>
          </ray>
        </sensor>
      </link>




      <!-- Fixed Joints for Arms -->
      <joint name="arm_1_joint" type="fixed">
        <parent>center_cylinder</parent>
        <child>arm_1</child>
      </joint>

      <joint name="arm_2_joint" type="fixed">
        <parent>center_cylinder</parent>
        <child>arm_2</child>
      </joint>

      <joint name="arm_3_joint" type="fixed">
        <parent>center_cylinder</parent>
        <child>arm_3</child>
      </joint>

      <joint name="arm_4_joint" type="fixed">
        <parent>center_cylinder</parent>
        <child>arm_4</child>
      </joint>
  


      <!-- Joints -->
      <joint name="rotor_1_joint" type="revolute">
        <parent>arm_1</parent>
        <child>rotor_1</child>
        <axis>
          <xyz>0 0 1</xyz>
        </axis>
      </joint>

      <joint name="rotor_2_joint" type="revolute">
        <parent>arm_2</parent>
        <child>rotor_2</child>
        <axis>
          <xyz>0 0 1</xyz>
        </axis>
      </joint>

      <joint name="rotor_3_joint" type="revolute">
        <parent>arm_3</parent>
        <child>rotor_3</child>
        <axis>
          <xyz>0 0 1</xyz>
        </axis>
      </joint>

      <joint name="rotor_4_joint" type="revolute">
        <parent>arm_4</parent>
        <child>rotor_4</child>
        <axis>
          <xyz>0 0 1</xyz>
        </axis>
      </joint>

      <!-- Fixed Joints for Sensors -->
      <joint name="lidar_joint" type="fixed">
        <parent>center_cylinder</parent>
        <child>lidar</child>
      </joint>
      
      <joint name="ultrasonic1_joint" type="fixed">
        <parent>center_cylinder</parent>
        <child>ultrasonic_1</child>
      </joint>
      
      <joint name="ultrasonic2_joint" type="fixed">
        <parent>center_cylinder</parent>
        <child>ultrasonic_2</child>
      </joint>

      <joint name="ultrasonic3_joint" type="fixed">
        <parent>center_cylinder</parent>
        <child>ultrasonic_3</child>
      </joint>

      <joint name="ultrasonic4_joint" type="fixed">
        <parent>center_cylinder</parent>
        <child>ultrasonic_4</child>
      </joint>
    </model>


    <!--Environment-->
    <model name="Obstacles">
      <link name="Obstacle1">
        <pose> 10 5 0 0 0 0</pose>
        <visual name="Obstacle1">
          <geometry>
            <box>
              <size>1 1 5</size>
            </box>
          </geometry>
          <material>
            <ambient>1 0 0 1</ambient>
            <diffuse>1 0 0 1</diffuse>
          </material>
        </visual>
        <collision name="collision">
          <geometry>
            <box>
              <size>1 1 5</size>
            </box>
          </geometry>
        </collision>
      </link>

      <link name="Obstacle2">
      <pose> -5 -7 0 0 0 0</pose>
        <visual name="visual">
          <geometry>
            <box>
              <size>1 2 10</size>
            </box>
          </geometry>
          <material>
            <ambient>1 0 0 1</ambient>
            <diffuse>1 0 0 1</diffuse>
          </material>
        </visual>
        <collision name="collision">
          <geometry>
            <box>
              <size>1 2 10</size>
            </box>
          </geometry>
        </collision>
      </link>

      <link name="Obstacle3">
      <pose> 3 -7 0 0 0 0</pose>
        <visual name="visual">
          <geometry>
            <box>
              <size>2 2 7.5</size>
            </box>
          </geometry>
          <material>
            <ambient>1 0 0 1</ambient>
            <diffuse>1 0 0 1</diffuse>
          </material>
        </visual>
        <collision name="collision">
          <geometry>
            <box>
              <size>2 2 7.5</size>
            </box>
          </geometry>
        </collision>
      </link>

      <link name="Obstacle4">
      <pose> -3 7 0 0 0 0</pose>
        <visual name="visual">
          <geometry>
            <box>
              <size>1 2 2.5</size>
            </box>
          </geometry>
          <material>
            <ambient>1 0 0 1</ambient>
            <diffuse>1 0 0 1</diffuse>
          </material>
        </visual>
        <collision name="collision">
          <geometry>
            <box>
              <size>1 2 2.5</size>
            </box>
          </geometry>
        </collision>
      </link>
    </model>

    <!-- Physics -->
    <physics type="ode">
      <max_step_size>0.001</max_step_size>
      <real_time_factor>1</real_time_factor>
      <real_time_update_rate>100</real_time_update_rate>
    </physics>

    <!-- Gravity -->
    <gravity>0 0 -9.81</gravity>

    <plugin name="GazeboPlugin" filename="lib/libGazeboCoSimPlugin.so"><portNumber>14581</portNumber></plugin>
  </world>
</sdf>